<?xml version="1.0" encoding="UTF-8"?>
<!-- Generated by org.testng.reporters.JUnitReportReporter -->
<testsuite hostname="DESKTOP-H4ANUV3" name="TestNG.MyApplication" tests="3" failures="1" timestamp="20 Apr 2019 18:18:19 GMT" time="0.020" errors="2">
  <testcase name="startApp" time="0.020" classname="TestNG.MyApplication">
    <failure type="java.lang.AssertionError" message="expected [13] but found [12]">
      <![CDATA[java.lang.AssertionError: expected [13] but found [12]
	at org.testng.Assert.fail(Assert.java:94)
	at org.testng.Assert.failNotEquals(Assert.java:496)
	at org.testng.Assert.assertEquals(Assert.java:125)
	at org.testng.Assert.assertEquals(Assert.java:372)
	at org.testng.Assert.assertEquals(Assert.java:382)
	at TestNG.MyApplication.startApp(MyApplication.java:10)
	at sun.reflect.NativeMethodAccessorImpl.invoke0(Native Method)
	at sun.reflect.NativeMethodAccessorImpl.invoke(Unknown Source)
	at sun.reflect.DelegatingMethodAccessorImpl.invoke(Unknown Source)
	at java.lang.reflect.Method.invoke(Unknown Source)
	at org.testng.internal.MethodInvocationHelper.invokeMethod(MethodInvocationHelper.java:85)
	at org.testng.internal.Invoker.invokeMethod(Invoker.java:639)
	at org.testng.internal.Invoker.invokeTestMethod(Invoker.java:816)
	at org.testng.internal.Invoker.invokeTestMethods(Invoker.java:1124)
	at org.testng.internal.TestMethodWorker.invokeTestMethods(TestMethodWorker.java:125)
	at org.testng.internal.TestMethodWorker.run(TestMethodWorker.java:108)
	at org.testng.TestRunner.privateRun(TestRunner.java:774)
	at org.testng.TestRunner.run(TestRunner.java:624)
	at org.testng.SuiteRunner.runTest(SuiteRunner.java:359)
	at org.testng.SuiteRunner.runSequentially(SuiteRunner.java:354)
	at org.testng.SuiteRunner.privateRun(SuiteRunner.java:312)
	at org.testng.SuiteRunner.run(SuiteRunner.java:261)
	at org.testng.SuiteRunnerWorker.runSuite(SuiteRunnerWorker.java:52)
	at org.testng.SuiteRunnerWorker.run(SuiteRunnerWorker.java:86)
	at org.testng.TestNG.runSuitesSequentially(TestNG.java:1215)
	at org.testng.TestNG.runSuitesLocally(TestNG.java:1140)
	at org.testng.TestNG.run(TestNG.java:1048)
	at org.testng.remote.RemoteTestNG.run(RemoteTestNG.java:112)
	at org.testng.remote.RemoteTestNG.initAndRun(RemoteTestNG.java:205)
	at org.testng.remote.RemoteTestNG.main(RemoteTestNG.java:176)
]]>
    </failure>
  </testcase> <!-- startApp -->
  <testcase name="loginApp" time="0.000" classname="TestNG.MyApplication">
    <error type="java.lang.Throwable" message="Method MyApplication.loginApp()[pri:0, instance:TestNG.MyApplication@73035e27] depends on not successfully finished methods">
      <![CDATA[java.lang.Throwable: Method MyApplication.loginApp()[pri:0, instance:TestNG.MyApplication@73035e27] depends on not successfully finished methods
	at org.testng.internal.Invoker.invokeTestMethods(Invoker.java:1033)
	at org.testng.internal.TestMethodWorker.invokeTestMethods(TestMethodWorker.java:125)
	at org.testng.internal.TestMethodWorker.run(TestMethodWorker.java:108)
	at org.testng.TestRunner.privateRun(TestRunner.java:774)
	at org.testng.TestRunner.run(TestRunner.java:624)
	at org.testng.SuiteRunner.runTest(SuiteRunner.java:359)
	at org.testng.SuiteRunner.runSequentially(SuiteRunner.java:354)
	at org.testng.SuiteRunner.privateRun(SuiteRunner.java:312)
	at org.testng.SuiteRunner.run(SuiteRunner.java:261)
	at org.testng.SuiteRunnerWorker.runSuite(SuiteRunnerWorker.java:52)
	at org.testng.SuiteRunnerWorker.run(SuiteRunnerWorker.java:86)
	at org.testng.TestNG.runSuitesSequentially(TestNG.java:1215)
	at org.testng.TestNG.runSuitesLocally(TestNG.java:1140)
	at org.testng.TestNG.run(TestNG.java:1048)
	at org.testng.remote.RemoteTestNG.run(RemoteTestNG.java:112)
	at org.testng.remote.RemoteTestNG.initAndRun(RemoteTestNG.java:205)
	at org.testng.remote.RemoteTestNG.main(RemoteTestNG.java:176)
]]>
    </error>
  </testcase> <!-- loginApp -->
  <testcase name="logOutApp" time="0.000" classname="TestNG.MyApplication">
    <error type="java.lang.Throwable" message="Method MyApplication.logOutApp()[pri:0, instance:TestNG.MyApplication@73035e27] depends on not successfully finished methods">
      <![CDATA[java.lang.Throwable: Method MyApplication.logOutApp()[pri:0, instance:TestNG.MyApplication@73035e27] depends on not successfully finished methods
	at org.testng.internal.Invoker.invokeTestMethods(Invoker.java:1033)
	at org.testng.internal.TestMethodWorker.invokeTestMethods(TestMethodWorker.java:125)
	at org.testng.internal.TestMethodWorker.run(TestMethodWorker.java:108)
	at org.testng.TestRunner.privateRun(TestRunner.java:774)
	at org.testng.TestRunner.run(TestRunner.java:624)
	at org.testng.SuiteRunner.runTest(SuiteRunner.java:359)
	at org.testng.SuiteRunner.runSequentially(SuiteRunner.java:354)
	at org.testng.SuiteRunner.privateRun(SuiteRunner.java:312)
	at org.testng.SuiteRunner.run(SuiteRunner.java:261)
	at org.testng.SuiteRunnerWorker.runSuite(SuiteRunnerWorker.java:52)
	at org.testng.SuiteRunnerWorker.run(SuiteRunnerWorker.java:86)
	at org.testng.TestNG.runSuitesSequentially(TestNG.java:1215)
	at org.testng.TestNG.runSuitesLocally(TestNG.java:1140)
	at org.testng.TestNG.run(TestNG.java:1048)
	at org.testng.remote.RemoteTestNG.run(RemoteTestNG.java:112)
	at org.testng.remote.RemoteTestNG.initAndRun(RemoteTestNG.java:205)
	at org.testng.remote.RemoteTestNG.main(RemoteTestNG.java:176)
]]>
    </error>
  </testcase> <!-- logOutApp -->
</testsuite> <!-- TestNG.MyApplication -->
